2024-07-29 18:15:04.754474
Exception in thread Thread-1:
Traceback (most recent call last):
  File "C:\Program Files\Python39\lib\threading.py", line 973, in _bootstrap_inner
    self.run()
  File "C:\Program Files\Python39\lib\threading.py", line 910, in run
    self._target(*self._args, **self._kwargs)
  File "C:\Users\User\Downloads\GitHub\elsiros\Elsiros\controllers\Robofest_TEAM\main_pb.py", line 118, in main_procedure
    robot = CommunicationManager(1, '127.0.0.1', int(Port), logarg, team_color=sys.argv[3].upper(), player_number = int(sys.argv[4]), time_step = 25)
  File "C:\Users\User\Downloads\GitHub\elsiros\Elsiros\controllers\player\communication_manager_robokit.py", line 14, in __init__
